# Panic

- Sometimes, bad things happen in your code, and there’s nothing you can do about it. In these cases, Rust has the `panic!` macro.

> By default, when a panic occurs, the program starts _unwinding_, which means Rust walks back up the stack and cleans up the data. You can switch from unwinding to aborting upon a panic by adding `panic = 'abort'` to the appropriate `[profile]` sections in your _Cargo.toml_ file.

```rust
fn main() {
    panic!("crash and burn");
}
```

```
$ cargo run
   Compiling panic v0.1.0 (file:///projects/panic)
    Finished dev [unoptimized + debuginfo] target(s) in 0.25s
     Running `target/debug/panic`
thread 'main' panicked at 'crash and burn', src/main.rs:2:5
note: run with `RUST_BACKTRACE=1` environment variable to display a backtrace
```

- The call to `panic!` causes the error message contained in the last two lines.
	- _src/main.rs:2:5_ indicates that it’s the second line, fifth character of our _src/main.rs_ file.

```rust
fn main() {
    let v = vec![1, 2, 3];

    v[99];
}
```

```
$ cargo run
   Compiling panic v0.1.0 (file:///projects/panic)
    Finished dev [unoptimized + debuginfo] target(s) in 0.27s
     Running `target/debug/panic`
thread 'main' panicked at 'index out of bounds: the len is 3 but the index is 99', src/main.rs:4:5
note: run with `RUST_BACKTRACE=1` environment variable to display a backtrace
```

```
$ RUST_BACKTRACE=1 cargo run
thread 'main' panicked at 'index out of bounds: the len is 3 but the index is 99', src/main.rs:4:5
stack backtrace:
   0: rust_begin_unwind
             at /rustc/7eac88abb2e57e752f3302f02be5f3ce3d7adfb4/library/std/src/panicking.rs:483
   1: core::panicking::panic_fmt
             at /rustc/7eac88abb2e57e752f3302f02be5f3ce3d7adfb4/library/core/src/panicking.rs:85
   2: core::panicking::panic_bounds_check
             at /rustc/7eac88abb2e57e752f3302f02be5f3ce3d7adfb4/library/core/src/panicking.rs:62
   3: <usize as core::slice::index::SliceIndex<[T]>>::index
             at /rustc/7eac88abb2e57e752f3302f02be5f3ce3d7adfb4/library/core/src/slice/index.rs:255
   4: core::slice::index::<impl core::ops::index::Index<I> for [T]>::index
             at /rustc/7eac88abb2e57e752f3302f02be5f3ce3d7adfb4/library/core/src/slice/index.rs:15
   5: <alloc::vec::Vec<T> as core::ops::index::Index<I>>::index
             at /rustc/7eac88abb2e57e752f3302f02be5f3ce3d7adfb4/library/alloc/src/vec.rs:1982
   6: panic::main
             at ./src/main.rs:4
   7: core::ops::function::FnOnce::call_once
             at /rustc/7eac88abb2e57e752f3302f02be5f3ce3d7adfb4/library/core/src/ops/function.rs:227
note: Some details are omitted, run with `RUST_BACKTRACE=full` for a verbose backtrace.
```

- We can set the `RUST_BACKTRACE` environment variable to get a backtrace of exactly what happened to cause the error.
- In order to get backtraces with this information, debug symbols must be enabled. Debug symbols are enabled by default when using `cargo build` or `cargo run` without the `--release` flag.

# Result

```rust
enum Result<T, E> {
    Ok(T),
    Err(E),
}
```

- `Result` enum is defined as having two variants, `Ok` and `Err`
- `T` represents the type of the value that will be returned in a success case within the `Ok` variant
- `E` represents the type of the error that will be returned in a failure case within the `Err` variant.

```rust
use std::fs::File;

fn main() {
    let greeting_file_result = File::open("hello.txt");

    let greeting_file = match greeting_file_result {
        Ok(file) => file,
        Err(error) => panic!("Problem opening the file: {:?}", error),
    };
}
```

- Like the `Option` enum, the `Result` enum and its variants have been brought into scope by the prelude, so we don’t need to specify `Result::` before the `Ok` and `Err` variants in the `match` arms.

## Different Errors

```rust
use std::fs::File;
use std::io::ErrorKind;

fn main() {
    let greeting_file_result = File::open("hello.txt");

    let greeting_file = match greeting_file_result {
        Ok(file) => file,
        Err(error) => match error.kind() {
            ErrorKind::NotFound => match File::create("hello.txt") {
                Ok(fc) => fc,
                Err(e) => panic!("Problem creating the file: {:?}", e),
            },
            other_error => {
                panic!("Problem opening the file: {:?}", other_error);
            }
        },
    };
}
```

- The type of the value that `File::open` returns inside the `Err` variant is `io::Error`, which is a struct provided by the standard library. This struct has a method `kind` that we can call to get an `io::ErrorKind` value
- The enum `io::ErrorKind` is provided by the standard library and has variants representing the different kinds of errors that might result from an `io` operation

```rust
use std::fs::File;
use std::io::ErrorKind;

fn main() {
    let greeting_file = File::open("hello.txt").unwrap_or_else(|error| {
        if error.kind() == ErrorKind::NotFound {
            File::create("hello.txt").unwrap_or_else(|error| {
                panic!("Problem creating the file: {:?}", error);
            })
        } else {
            panic!("Problem opening the file: {:?}", error);
        }
    });
}
```

- It’s another way to write the same logic, this time using closures and the `unwrap_or_else` method.
- Many more of these methods can clean up huge nested `match` expressions when you’re dealing with errors.

## Error: unwrap and expect

Using `match` works well enough, but it can be a bit verbose and doesn’t always communicate intent well. The `Result<T, E>` type has many helper methods defined on it to do various, more specific tasks.

```rust
use std::fs::File;

fn main() {
    let greeting_file = File::open("hello.txt").unwrap();
}
```

- The `unwrap` method is a shortcut method implemented just like the `match` expression we wrote. If the `Result` value is the `Ok` variant, `unwrap` will return the value inside the `Ok`. If the `Result` is the `Err` variant, `unwrap` will call the `panic!` macro for us

```rust
use std::fs::File;

fn main() {
    let greeting_file = File::open("hello.txt")
        .expect("hello.txt should be included in this project");
}
```

- The `expect` method lets us also choose the `panic!` error message. Using `expect` instead of `unwrap` and providing good error messages can convey your intent and make tracking down the source of a panic easier.

> In production-quality code, most Rustaceans choose `expect` rather than `unwrap` and give more context about why the operation is expected to always succeed.

## Propagating Errors

- When a function’s implementation calls something that might fail, instead of handling the error within the function itself, you can return the error to the calling code so that it can decide what to do.

```rust
use std::fs::File;
use std::io::{self, Read};

fn read_username_from_file() -> Result<String, io::Error> {
    let username_file_result = File::open("hello.txt");

    let mut username_file = match username_file_result {
        Ok(file) => file,
        Err(e) => return Err(e),
    };

    let mut username = String::new();

    match username_file.read_to_string(&mut username) {
        Ok(_) => Ok(username),
        Err(e) => Err(e),
    }
}

```

- If this function succeeds without any problems, the code that calls this function will receive an `Ok` value that holds a `String`—the username that this function read from the file.
- We chose `io::Error` as the return type of this function because that happens to be the type of the error value returned from both of the operations we’re calling in this function’s body that might fail: the `File::open` function and the `read_to_string` method.

> This pattern of propagating errors is so common in Rust that Rust provides the question mark operator `?` to make this easier.

### ? Operator

```rust
use std::fs::File;
use std::io::{self, Read};

fn read_username_from_file() -> Result<String, io::Error> {
    let mut username_file = File::open("hello.txt")?;
    let mut username = String::new();
    username_file.read_to_string(&mut username)?;
    Ok(username)
}
```

- The `?` placed after a `Result` value is defined to work:
	- If the value of the `Result` is an `Ok`, the value inside the `Ok` will get returned from this expression, and the program will continue.
	- If the value is an `Err`, the `Err` will be returned from the whole function as if we had used the `return` keyword so the error value gets propagated to the calling code.

- There is a difference between is that error values that have the `?` operator called on them go through the `from` function, which is used to convert values from one type into another.
	- For example, we could change the `read_username_from_file` function to return a custom error type named `OurError` that we define. If we also define `impl From<io::Error> for OurError` to construct an instance of `OurError` from an `io::Error`

```rust
use std::fs::File;
use std::io::{self, Read};

fn read_username_from_file() -> Result<String, io::Error> {
    let mut username = String::new();

    File::open("hello.txt")?.read_to_string(&mut username)?;

    Ok(username)
}
```

- The `?` operator eliminates a lot of boilerplate and makes this function’s implementation simpler. We could even shorten this code further by chaining method calls immediately after the `?`

```rust
use std::fs;
use std::io;

fn read_username_from_file() -> Result<String, io::Error> {
    fs::read_to_string("hello.txt")
}
```

- Reading a file into a string is a fairly common operation, so the standard library provides the convenient `fs::read_to_string` function that opens the file, creates a new `String`, reads the contents of the file, puts the contents into that `String`, and returns it.

#### Restriction

```
$ cargo run
   Compiling error-handling v0.1.0 (file:///projects/error-handling)
error[E0277]: the `?` operator can only be used in a function that returns `Result` or `Option` (or another type that implements `FromResidual`)
 --> src/main.rs:4:48
  |
3 | fn main() {
  | --------- this function should return `Result` or `Option` to accept `?`
4 |     let greeting_file = File::open("hello.txt")?;
  |                                                ^ cannot use the `?` operator in a function that returns `()`
  |
  = help: the trait `FromResidual<Result<Infallible, std::io::Error>>` is not implemented for `()`

For more information about this error, try `rustc --explain E0277`.
error: could not compile `error-handling` due to previous error

```

- The `?` operator can only be used in functions whose return type is compatible with the value the `?` is used on.
- To fix the error, you have two choices.
	1. Change the return type of your function to be compatible with the value you’re using the `?` operator
	2. The other technique is to use a `match` or one of the `Result<T, E>` methods to handle the `Result<T, E>` in whatever way is appropriate


```rust
fn last_char_of_first_line(text: &str) -> Option<char> {
    text.lines().next()?.chars().last()
}
```

- The behavior of the `?` operator when called on an `Option<T>` is similar to its behavior when called on a `Result<T, E>`: if the value is `None`, the `None` will be returned early from the function at that point. If the value is `Some`, the value inside the `Some` is the resulting value of the expression and the function continues.

- If we couldn’t use the `?` operator on `Option`, we’d have to implement this logic using more method calls or a `match` expression.

> The `?` operator won’t automatically convert a `Result` to an `Option` or vice versa; in those cases, you can use methods like the `ok` method on `Result` or the `ok_or` method on `Option` to do the conversion explicitly.


```rust
use std::error::Error;
use std::fs::File;

fn main() -> Result<(), Box<dyn Error>> {
    let greeting_file = File::open("hello.txt")?;

    Ok(())
}
```

- `main` can also return a `Result<(), E>`
- The `Box<dyn Error>` type is a _trait object_. You can read `Box<dyn Error>` to mean “any kind of error.”
- When a `main` function returns a `Result<(), E>`, the executable will exit with a value of `0` if `main` returns `Ok(())` and will exit with a nonzero value if `main` returns an `Err` value.

# Panic! or not panic!

- When code panics, there’s no way to recover.
- When you choose to return a `Result` value, you give the calling code options. Therefore, returning `Result` is a good default choice when you’re defining a function that might fail.

> In situations such as examples, prototype code, and tests, it’s more appropriate to write code that panics instead of returning a `Result`